Workbook

Sheet Questions
A2: Business Case : | B2: The following is the data for a Movie Rental Shop.
B3: The different sheets contains different data for this shop , using these information available in the sheets complete the questions below
A5: SI.No | B5: Questions | C5: Marks
A6: 1 | B6: In the Customer, Rental Transaction, and Movie sheets, certain columns (highlighted in yellow) are missing data. Update these columns using the data available in the other sheets. | C6: 5
A7: 2 | B7: In the customer table, create a column named "BLU-RAY Movies Transactions (%)" (column highlighted in red font) and calculate the percentage of transactions involving BLU-RAY Format movies out of the total transactions for the corresponding customer. Hint: BLU-RAY Movies Transactions (%) = (Total number of transactions with BLU-RAY movies) / (Total transactions). | C7: 5
A8: 3 | B8: Create a Pivot Table to display the Total Price and Average Price based on the Studio. Sort the data in descending order based on the Total Price. (Provide your solution in the sheet labeled "Q3"). | C8: 6
A9: 4 | B9: Identify the highest revenue-collecting studio for each year. If multiple studios have the highest earnings for a particular year, list all of them. - Hint: First, add the Transaction Date to the Rental Transaction Line Item data, then create a Pivot Table using the full data accordingly. (Provide your solution in the sheet labeled "Q4"). | C9: 6
A10: 5 | B10: Create a Pivot Table to calculate the Year-over-Year (YoY) change in total sales for the "A24" and "Fox" studios, and generate an appropriate Pivot Chart to visualize the data. - Ensure the chart has a proper title and is aligned correctly. (Provide your solution in the sheet labeled "Q5"). | C10: 8

Sheet Customer
A1: CustomerID | B1: First | C1: Last | D1: StreetAddress | E1: City | F1: Email | G1: MemberSince | H1: SubscribedToEmailList | I1: Gender | J1: Total No of Transactions | K1: Total Amount | L1: BLU-RAY Movies Transactions (%)
A2: 101811 | B2: Kenneth | C2: Walton | D2: 6715 Commonwealth Dr | E2: Sacramento | F2: walton.k76@fastmail.com | G2: 41424 | H2: FALSE | I2: M | J2: =COUNTIF('Rental Transaction'!B2:B3873,A2) -> 5 | K2: =SUMIF('Rental Transaction'!B:B,A2,'Rental Transaction'!H:H) -> 25 | L2: =COUNTIFS('Retal Tran Line Item'!D:D,"BLU-RAY",'Retal Tran Line Item'!H:H,A2)/J2 -> 0.6
A3: 103508 | B3: Madeleine | C3: Jones | D3: 3603 Leola Way | E3: Sacramento | F3: j_madeleine@gmail.com | G3: 41311 | H3: FALSE | I3: F | J3: =COUNTIF('Rental Transaction'!B3:B3874,A3) -> 6 | K3: =SUMIF('Rental Transaction'!B:B,A3,'Rental Transaction'!H:H) -> 42 | L3: =COUNTIFS('Retal Tran Line Item'!D:D,"BLU-RAY",'Retal Tran Line Item'!H:H,A3)/J3 -> 0.5
A4: 104939 | B4: Damen | C4: Wheeler | D4: 6740 Branwood Way | E4: Orangevale | F4: dwheeler@outlook.com | G4: 41375 | H4: FALSE | I4: M | J4: =COUNTIF('Rental Transaction'!B4:B3875,A4) -> 5 | K4: =SUMIF('Rental Transaction'!B:B,A4,'Rental Transaction'!H:H) -> 52 | L4: =COUNTIFS('Retal Tran Line Item'!D:D,"BLU-RAY",'Retal Tran Line Item'!H:H,A4)/J4 -> 0.8
A5: 105549 | B5: Kevin | C5: Gilbert | D5: 3198 Livingston Way | E5: Folsom | F5: kgilbert@fastmail.com | G5: 41333 | H5: TRUE | I5: M | J5: =COUNTIF('Rental Transaction'!B5:B3876,A5) -> 4 | K5: =SUMIF('Rental Transaction'!B:B,A5,'Rental Transaction'!H:H) -> 29 | L5: =COUNTIFS('Retal Tran Line Item'!D:D,"BLU-RAY",'Retal Tran Line Item'!H:H,A5)/J5 -> 0.75
A6: 105771 | B6: John | C6: Young | D6: 663 Westward Way | E6: Sacramento | F6: john.y90@mail.com | G6: 41522 | H6: TRUE | I6: M | J6: =COUNTIF('Rental Transaction'!B6:B3877,A6) -> 5 | K6: =SUMIF('Rental Transaction'!B:B,A6,'Rental Transaction'!H:H) -> 47 | L6: =COUNTIFS('Retal Tran Line Item'!D:D,"BLU-RAY",'Retal Tran Line Item'!H:H,A6)/J6 -> 0.4
A7: 108708 | B7: Tommy | C7: Kono | D7: 3179 Camelia River Way | E7: Isleton | F7: tkono@outlook.com | G7: 41091 | H7: FALSE | I7: M | J7: =COUNTIF('Rental Transaction'!B7:B3878,A7) -> 8 | K7: =SUMIF('Rental Transaction'!B:B,A7,'Rental Transaction'!H:H) -> 58 | L7: =COUNTIFS('Retal Tran Line Item'!D:D,"BLU-RAY",'Retal Tran Line Item'!H:H,A7)/J7 -> 0.5
A8: 109251 | B8: Anna | C8: Himes | D8: 5507 Chimango Way | E8: Sacramento | F8: h_anna@fastmail.com | G8: 41208 | H8: TRUE | I8: F | J8: =COUNTIF('Rental Transaction'!B8:B3879,A8) -> 8 | K8: =SUMIF('Rental Transaction'!B:B,A8,'Rental Transaction'!H:H) -> 81 | L8: =COUNTIFS('Retal Tran Line Item'!D:D,"BLU-RAY",'Retal Tran Line Item'!H:H,A8)/J8 -> 0.75
A9: 110363 | B9: Marjorie | C9: Love | D9: 3462 Mellowoods Way | E9: Sacramento | F9: lmarjorie54@icloud.com | G9: 41508 | H9: TRUE | I9: F | J9: =COUNTIF('Rental Transaction'!B9:B3880,A9) -> 11 | K9: =SUMIF('Rental Transaction'!B:B,A9,'Rental Transaction'!H:H) -> 85 | L9: =COUNTIFS('Retal Tran Line Item'!D:D,"BLU-RAY",'Retal Tran Line Item'!H:H,A9)/J9 -> 1
A10: 111486 | B10: Nina | C10: Schreiner | D10: 1182 Dornajo Way | E10: Sacramento | F10: schreiner_n@mail.com | G10: 41395 | H10: FALSE | I10: F | J10: =COUNTIF('Rental Transaction'!B10:B3881,A10) -> 10 | K10: =SUMIF('Rental Transaction'!B:B,A10,'Rental Transaction'!H:H) -> 93 | L10: =COUNTIFS('Retal Tran Line Item'!D:D,"BLU-RAY",'Retal Tran Line Item'!H:H,A10)/J10 -> 0.6
A11: 111991 | B11: Marc | C11: Newfield | D11: 6887 Conklin Ct | E11: Sacramento | F11: mnewfield@icloud.com | G11: 41280 | H11: TRUE | I11: M | J11: =COUNTIF('Rental Transaction'!B11:B3882,A11) -> 8 | K11: =SUMIF('Rental Transaction'!B:B,A11,'Rental Transaction'!H:H) -> 58 | L11: =COUNTIFS('Retal Tran Line Item'!D:D,"BLU-RAY",'Retal Tran Line Item'!H:H,A11)/J11 -> 0.5
A12: 112690 | B12: Tom | C12: Hanks | D12: 9375 Ahart Way | E12: Ryde | F12: hanks_t5@mail.com | G12: 41154 | H12: FALSE | I12: M | J12: =COUNTIF('Rental Transaction'!B12:B3883,A12) -> 4 | K12: =SUMIF('Rental Transaction'!B:B,A12,'Rental Transaction'!H:H) -> 27 | L12: =COUNTIFS('Retal Tran Line Item'!D:D,"BLU-RAY",'Retal Tran Line Item'!H:H,A12)/J12 -> 0.5
A13: 116690 | B13: Christian | C13: Wellisch | D13: 8725 Capistrano Way | E13: Sacramento | F13: wellisch.c@mail.com | G13: 41332 | H13: FALSE | I13: M | J13: =COUNTIF('Rental Transaction'!B13:B3884,A13) -> 6 | K13: =SUMIF('Rental Transaction'!B:B,A13,'Rental Transaction'!H:H) -> 63 | L13: =COUNTIFS('Retal Tran Line Item'!D:D,"BLU-RAY",'Retal Tran Line Item'!H:H,A13)/J13 -> 0.33333333
... A555: 999915 | B555: Ricky | C555: Ray | D555: 7837 El Cerro Ct | E555: Sacramento | F555: ricky_r@mail.com | G555: 41475 | H555: FALSE | I555: M | J555: =COUNTIF('Rental Transaction'!B555:B4426,A555) -> 11 | K555: =SUMIF('Rental Transaction'!B:B,A555,'Rental Transaction'!H:H) -> 139 | L555: =COUNTIFS('Retal Tran Line Item'!D:D,"BLU-RAY",'Retal Tran Line Item'!H:H,A555)/J555 -> 0.45454545

Sheet Rental Transaction
A1: | | B1: CustomerID | C1: TransactionDate | D1: CC-Type | E1: LocationID | F1: Month Name | G1: Week Number in year | H1: Total Price
A2: 100000 | B2: 864896 | C2: 41097 | D2: Discover | E2: 2 | F2: =TEXT(C2,"MMMM") -> July | G2: =WEEKNUM(C2) -> 27 | H2: =SUMIF('Retal Tran Line Item'!E:E,A2,'Retal Tran Line Item'!B:B) -> 25 | J2: =COUNTIF('Rental Transaction'!B2:B3873,A2,'Rental Transaction'!H2'Rental Transaction'!H2 | K2: =SUMIF('Rental Transaction'!B2
A3: 100001 | B3: 610766 | C3: 41103 | D3: Visa | E3: 1 | F3: =TEXT(C3,"MMMM") -> July | G3: =WEEKNUM(C3) -> 28 | H3: =SUMIF('Retal Tran Line Item'!E:E,A3,'Retal Tran Line Item'!B:B) -> 5
A4: 100002 | B4: 207846 | C4: 41103 | D4: MasterCard | E4: 1 | F4: =TEXT(C4,"MMMM") -> July | G4: =WEEKNUM(C4) -> 28 | H4: =SUMIF('Retal Tran Line Item'!E:E,A4,'Retal Tran Line Item'!B:B) -> 11
A5: 100003 | B5: 166612 | C5: 41107 | D5: MasterCard | E5: 2 | F5: =TEXT(C5,"MMMM") -> July | G5: =WEEKNUM(C5) -> 29 | H5: =SUMIF('Retal Tran Line Item'!E:E,A5,'Retal Tran Line Item'!B:B) -> 7
A6: 100004 | B6: 482274 | C6: 41116 | D6: Visa | E6: 2 | F6: =TEXT(C6,"MMMM") -> July | G6: =WEEKNUM(C6) -> 30 | H6: =SUMIF('Retal Tran Line Item'!E:E,A6,'Retal Tran Line Item'!B:B) -> 3
A7: 100005 | B7: 961080 | C7: 41118 | D7: Visa | E7: 2 | F7: =TEXT(C7,"MMMM") -> July | G7: =WEEKNUM(C7) -> 30 | H7: =SUMIF('Retal Tran Line Item'!E:E,A7,'Retal Tran Line Item'!B:B) -> 7
A8: 100006 | B8: 736500 | C8: 41121 | D8: MasterCard | E8: 1 | F8: =TEXT(C8,"MMMM") -> July | G8: =WEEKNUM(C8) -> 31 | H8: =SUMIF('Retal Tran Line Item'!E:E,A8,'Retal Tran Line Item'!B:B) -> 15
A9: 100007 | B9: 714277 | C9: 41122 | D9: American Express | E9: 2 | F9: =TEXT(C9,"MMMM") -> August | G9: =WEEKNUM(C9) -> 31 | H9: =SUMIF('Retal Tran Line Item'!E:E,A9,'Retal Tran Line Item'!B:B) -> 2
A10: 100008 | B10: 324435 | C10: 41123 | D10: Visa | E10: 2 | F10: =TEXT(C10,"MMMM") -> August | G10: =WEEKNUM(C10) -> 31 | H10: =SUMIF('Retal Tran Line Item'!E:E,A10,'Retal Tran Line Item'!B:B) -> 4
A11: 100009 | B11: 207846 | C11: 41126 | D11: MasterCard | E11: 2 | F11: =TEXT(C11,"MMMM") -> August | G11: =WEEKNUM(C11) -> 32 | H11: =SUMIF('Retal Tran Line Item'!E:E,A11,'Retal Tran Line Item'!B:B) -> 3
A12: 100010 | B12: 862302 | C12: 41126 | D12: Visa | E12: 2 | F12: =TEXT(C12,"MMMM") -> August | G12: =WEEKNUM(C12) -> 32 | H12: =SUMIF('Retal Tran Line Item'!E:E,A12,'Retal Tran Line Item'!B:B) -> 12
A13: 100011 | B13: 274541 | C13: 41130 | D13: MasterCard | E13: 1 | F13: =TEXT(C13,"MMMM") -> August | G13: =WEEKNUM(C13) -> 32 | H13: =SUMIF('Retal Tran Line Item'!E:E,A13,'Retal Tran Line Item'!B:B) -> 6
A14: 100012 | B14: 789308 | C14: 41130 | D14: MasterCard | E14: 2 | F14: =TEXT(C14,"MMMM") -> August | G14: =WEEKNUM(C14) -> 32 | H14: =SUMIF('Retal Tran Line Item'!E:E,A14,'Retal Tran Line Item'!B:B) -> 9
... A3873: 104813 | B3873: 480298 | C3873: 41897 | D3873: MasterCard | E3873: 1 | F3873: =TEXT(C3873,"MMMM") -> September | G3873: =WEEKNUM(C3873) -> 38 | H3873: =SUMIF('Retal Tran Line Item'!E:E,A3873,'Retal Tran Line Item'!B:B) -> 8

Sheet Retal Tran Line Item
A1: MovieID | B1: Price | C1: ReturnDate | D1: Format | E1: TransactionID | F1: LineItemID | G1: Studio | H1: CustomerID | I1: Year
A2: 10208 | B2: 5 | C2: 41100 | D2: DVD | E2: 100000 | F2: AB100000 | G2: =VLOOKUP(A2,Movie!A:D,4,FALSE) -> Warner Brothers | H2: =VLOOKUP(E2,'Rental Transaction'!A:B,2,FALSE) -> 864896 | I2: =YEAR(C2) -> 2012
A3: 10207 | B3: 6 | C3: 41098 | D3: DVD | E3: 100000 | F3: AB100001 | G3: =VLOOKUP(A3,Movie!A:D,4,FALSE) -> Paramount | H3: =VLOOKUP(E3,'Rental Transaction'!A:B,2,FALSE) -> 864896 | I3: =YEAR(C3) -> 2012
A4: 10168 | B4: 4 | C4: 41099 | D4: BLU-RAY | E4: 100000 | F4: AB100002 | G4: =VLOOKUP(A4,Movie!A:D,4,FALSE) -> Paramount | H4: =VLOOKUP(E4,'Rental Transaction'!A:B,2,FALSE) -> 864896 | I4: =YEAR(C4) -> 2012
A5: 10098 | B5: 10 | C5: 41098 | D5: BLU-RAY | E5: 100000 | F5: AB100003 | G5: =VLOOKUP(A5,Movie!A:D,4,FALSE) -> Warner Brothers | H5: =VLOOKUP(E5,'Rental Transaction'!A:B,2,FALSE) -> 864896 | I5: =YEAR(C5) -> 2012
A6: 10121 | B6: 5 | C6: 41104 | D6: DVD | E6: 100001 | F6: AB100004 | G6: =VLOOKUP(A6,Movie!A:D,4,FALSE) -> Weinstein Company | H6: =VLOOKUP(E6,'Rental Transaction'!A:B,2,FALSE) -> 610766 | I6: =YEAR(C6) -> 2012
A7: 10137 | B7: 1 | C7: 41104 | D7: BLU-RAY | E7: 100002 | F7: AB100005 | G7: =VLOOKUP(A7,Movie!A:D,4,FALSE) -> Buena Vista | H7: =VLOOKUP(E7,'Rental Transaction'!A:B,2,FALSE) -> 207846 | I7: =YEAR(C7) -> 2012
A8: 10124 | B8: 10 | C8: 41105 | D8: DVD | E8: 100002 | F8: AB100006 | G8: =VLOOKUP(A8,Movie!A:D,4,FALSE) -> Paramount | H8: =VLOOKUP(E8,'Rental Transaction'!A:B,2,FALSE) -> 207846 | I8: =YEAR(C8) -> 2012
A9: 10081 | B9: 7 | C9: 41108 | D9: DVD | E9: 100003 | F9: AB100007 | G9: =VLOOKUP(A9,Movie!A:D,4,FALSE) -> Weinstein Company | H9: =VLOOKUP(E9,'Rental Transaction'!A:B,2,FALSE) -> 166612 | I9: =YEAR(C9) -> 2012
A10: 10025 | B10: 2 | C10: 41117 | D10: DVD | E10: 100004 | F10: AB100008 | G10: =VLOOKUP(A10,Movie!A:D,4,FALSE) -> Sony | H10: =VLOOKUP(E10,'Rental Transaction'!A:B,2,FALSE) -> 482274 | I10: =YEAR(C10) -> 2012
A11: 10028 | B11: 1 | C11: 41117 | D11: DVD | E11: 100004 | F11: AB100009 | G11: =VLOOKUP(A11,Movie!A:D,4,FALSE) -> Summit Entertainment | H11: =VLOOKUP(E11,'Rental Transaction'!A:B,2,FALSE) -> 482274 | I11: =YEAR(C11) -> 2012
A12: 10080 | B12: 7 | C12: 41119 | D12: BLU-RAY | E12: 100005 | F12: AB100010 | G12: =VLOOKUP(A12,Movie!A:D,4,FALSE) -> Buena Vista | H12: =VLOOKUP(E12,'Rental Transaction'!A:B,2,FALSE) -> 961080 | I12: =YEAR(C12) -> 2012
A13: 10124 | B13: 8 | C13: 41122 | D13: BLU-RAY | E13: 100006 | F13: AB100011 | G13: =VLOOKUP(A13,Movie!A:D,4,FALSE) -> Paramount | H13: =VLOOKUP(E13,'Rental Transaction'!A:B,2,FALSE) -> 736500 | I13: =YEAR(C13) -> 2012
... A6311: 10237 | B6311: 8 | C6311: 41898 | D6311: DVD | E6311: 104813 | F6311: AB109196 | G6311: =VLOOKUP(A6311,Movie!A:D,4,FALSE) -> Warner Brothers | H6311: =VLOOKUP(E6311,'Rental Transaction'!A:B,2,FALSE) -> 480298 | I6311: =YEAR(C6311) -> 2014

Sheet Movie
A1: MovieID | B1: Title | C1: Year | D1: Studio
A2: 10000 | B2: Looper | C2: 2012 | D2: TriStar
A3: 10001 | B3: ParaNorman | C3: 2012 | D3: Focus
A4: 10002 | B4: Sinister | C4: 2012 | D4: Lionsgate
A5: 10003 | B5: Paranormal Activity 3 | C5: 2011 | D5: Paramount
A6: 10004 | B6: Paranormal Activity 4 | C6: 2012 | D6: Paramount
A7: 10005 | B7: The Lion King (in 3D) | C7: 2011 | D7: Buena Vista
A8: 10006 | B8: Footloose | C8: 2011 | D8: Paramount
A9: 10007 | B9: Arthur Christmas | C9: 2011 | D9: Sony
A10: 10008 | B10: The Ides of March | C10: 2011 | D10: Sony
A11: 10009 | B11: A Very Harold & Kumar 3D Christmas | C11: 2011 | D11: Warner Brothers
A12: 10010 | B12: Brave | C12: 2012 | D12: Buena Vista
A13: 10011 | B13: The Odd Life of Timothy Green | C13: 2012 | D13: Buena Vista
... A308: 10396 | B308: Magic in the Moonlight | C308: 2014 | D308: Sony Pictures Classics

Sheet Q3
A1: Studio | B1: Sum of Price | C1: Average of Price
A2: Warner Brothers | B2: 5893 | C2: 5.6284623
A3: Fox | B3: 4147 | C3: 5.5441176
A4: Universal | B4: 3830 | C4: 5.5749636
A5: Sony | B5: 3274 | C5: 5.4385382
A6: Paramount | B6: 3008 | C6: 5.5600739
A7: Buena Vista | B7: 2790 | C7: 5.4705882
A8: Lionsgate | B8: 2545 | C8: 5.4967603
A9: Weinstein Company | B9: 1579 | C9: 5.3890785
A10: Relativity | B10: 1333 | C10: 5.7956522
A11: Focus | B11: 975 | C11: 5.4166667
A12: TriStar | B12: 927 | C12: 5.0934066
A13: Screen Gems | B13: 878 | C13: 5.4197531
... A26: Grand Total | B26: 34923 | C26: 5.5345483

Sheet Q4
A1: Year | B1: Studio | C1: Sum of Price
A2: 2012 | B2: Buena Vista | C2: 172
B3: CBS Films | C3: 8
B4: FilmDistrict | C4: 22
B5: Focus | C5: 5
B6: Fox | C6: 278
B7: Fox Searchlight | C7: 1
B8: Lionsgate | C8: 78
B9: Open Road Films | C9: 27
B10: Paramount | C10: 265
B11: Relativity | C11: 50
B12: RM | C12: 14
B13: Screen Gems | C13: 72
B14: Sony | C14: 228
... B20: Weinstein Company | C20: 44
A21: 2012 Total | C21: 1958
A22: 2013 | B22: A24 | C22: 261
B23: Buena Vista | C23: 1833
B24: CBS Films | C24: 94
B25: FilmDistrict | C25: 479
B26: Focus | C26: 654
B27: Fox | C27: 2730
B28: Fox Searchlight | C28: 206
B29: Lionsgate | C29: 1764
B30: Open Road Films | C30: 497
B31: Paramount | C31: 2116
B32: Radius-TWC | C32: 63
B33: Relativity | C33: 910
B34: RM | C34: 123
... B44: Weinstein Company | C44: 1164
A45: 2013 Total | C45: 23717
A46: 2014 | B46: A24 | C46: 73
B47: Buena Vista | C47: 785
B48: CBS Films | C48: 16
B49: FilmDistrict | C49: 210
B50: Focus | C50: 316
B51: Fox | C51: 1139
B52: Fox Searchlight | C52: 212
B53: Lionsgate | C53: 703
B54: Open Road Films | C54: 168
...

Sheet Q5
A1: Sum of Price | B1: Studio
A2: Year | B2: A24 | C2: Fox | D2: Grand Total
A3: 2012 | C3: 278 | D3: 278
A4: 2013 | B4: 261 | C4: 2730 | D4: 2991
A5: 2014 | B5: 73 | C5: 1139 | D5: 1212
A6: Grand Total | B6: 334 | C6: 4147 | D6: 4481
